Workbook

Sheet 15-Day Curriculum
A1: Mail OPS – 15-Day Training Curriculum · iCloud Mail Trust & Safety Anti-Abuse
A2: Scope: inbound, outbound and Postmaster · 420 mins (7 hrs) of content per day · Draft for SME review, 22 Oct 2026 · Contains Apple Internal – Confidential material
A4: Day | B4: Topics | C4: Sub-Topics | D4: Objective | E4: Modality | F4: Time (mins) | G4: Remarks | H4: Guide ref (Module 1) | I4: Content status
A5: WEEK 1 · Foundations: product, mail flow, tools and the milter chain (Days 1–5)
A6: 1 | B6: Team Mission & Objectives - Mail OPS | C6: About Apple and its ecosystem About Apple's trust and safety What is Mail OPS | D6: Explain to new hires why the team exists, what the team does, and their roles and responsibilities | E6: SPL | F6: 75 | G6: The time includes 60 mins course and 15 mins trainer facilitation where he/she clarifies the doubts and concerns. | H6: §1 Mission and mindset | I6: Partly ready – SME to add
B7: Privacy principles and data handling boundaries | C7: Core principles and data types Handling data in investigations Incidents and mistakes GDPR | D7: Understand the core privacy principles that govern the team and know the do's and don'ts while handling user data | E7: SPL | F7: 45 | H7: §1 Privacy by design, §15 Guardrails | I7: Partly ready – SME to add
B8: iCloud and iCloud Mail | C8: Apple Account (DSID) and the product tree iCloud overview and iCloud basics iCloud Mail features and access methods How users report abuse | D8: Introduce the iCloud environment, the features and privileges an iCloud account comes with, and how users report abuse | E8: SPL | F8: 75 | G8: The time includes 60 mins course and 15 mins trainer facilitation where he/she clarifies the doubts and concerns. | H8: §2, §3, §11 | I8: Ready – Module 1 guide
B9: iCloud+ mail features | C9: Hide My Email iCloud Private Relay Custom Email Domain Mail Privacy Protection | D9: Explain the iCloud+ mail features, how Hide My Email forwarding works, and why these features matter for abuse work | E9: SPL | F9: 60 | G9: The time includes 45 mins course and 15 mins trainer facilitation where he/she clarifies the doubts and concerns. | H9: §2, §8 | I9: Ready – Module 1 guide
B10: Hands on: iCloud and iCloud+ Mail | C10: Create an account and add aliases Try Hide My Email and other iCloud+ features Rules, Junk and Mail Privacy Protection | D10: Create an iCloud account, add aliases, try iCloud+ and its available features. Send and receive mail through the account created and understand the process | E10: Activity | F10: 120 | H10: Guide: Week 1 tasks | I10: Ops to arrange
B11: Quick Wrap-Up | C11: Key takeaways Open questions Exit ticket | D11: Consolidate the day's learning and note open questions for the next day's recap | E11: Activity | F11: 45 | I11: Trainer to build
A12: 2 | B12: Day 1 Recap | C12: Round-robin questions on Day 1 topics Open questions from the wrap-up | D12: Check what trainees retained from Day 1 and close gaps before new content | E12: Activity | F12: 45 | I12: Trainer to build
B13: Mail flow architecture | C13: Inbound mail flow Outbound mail flow Email headers | D13: Know the inbound and outbound mail architectures and understand where filtering and policy enforcement happen. Also, be able to read an email header and judge authentication results | E13: Blended | F13: 90 | G13: The blended module - Trainees go through the self-paced module (60 mins), after which the trainer reinforces each workflow with the trainees (30 mins). | H13: §4, §5, §7, §14 Email fundamentals | I13: Ready – Module 1 guide
B14: Tool Overview: Heimdall | C14: What is Heimdall and its UI Email classification Naming convention Allowlist/Blocklist | D14: Understand how Heimdall classifies emails, the types of classifications, naming conventions, the Heimdall UI, and writing rules for blocking or allowing a campaign | E14: SPL | F14: 60 | H14: §6 stages 1 and 8, §14 | I14: Partly ready – SME to add
B15: Tool Walkthrough: Heimdall | C15: Live UI demo Reading existing rules Writing an allowlist or blocklist rule | D15: See Heimdall used live and follow how a rule is read and written end to end | E15: ILT | F15: 60 | I15: SME to provide
B16: URL/SUPs | C16: To be confirmed by SME | D16: Understand what URL/SUPs are, when they are used and how they are handled | E16: ILT | F16: 60 | G16: Placeholder time. URL/SUP is not defined in the Module 1 guide; SME to confirm content, modality and duration | I16: SME to provide
B17: Hands on: URL/SUPs | C17: Practice on sample URL/SUP requests | D17: Handle sample URL/SUP requests using the process covered in the session | E17: Activity | F17: 60 | G17: Placeholder time; depends on SME content | I17: SME to provide
B18: Quick Wrap-Up | C18: Key takeaways Open questions Exit ticket | D18: Consolidate the day's learning and note open questions for the next day's recap | E18: Activity | F18: 45 | I18: Trainer to build
A19: 3 | B19: Day 2 Recap | C19: Round-robin questions on Day 2 topics Open questions from the wrap-up | D19: Check what trainees retained from Day 2 and close gaps before new content | E19: Activity | F19: 45 | I19: Trainer to build
B20: Tools overview - part 1 (Splunk) - Investigate | C20: Which indexes we use How we write queries | D20: Know the various indexes used in Splunk and write queries | E20: Blended | F20: 90 | G20: The blended module - Trainees go through the self-paced module (60 mins), after which the trainer reinforces each workflow with the trainees (30 mins). | H20: §6 stage 9 (ETL), §10 Tools by stage | I20: SME to provide
B21: Hands on: Splunk | C21: Trainer does a round robin session with the trainees on Splunk indexes and queries | D21: Build a mental model of how indexes and queries are processed in Apple's systems | E21: Activity | F21: 30 | I21: SME to provide
B22: Tools overview - part 1 (Sonar) - Investigate | C22: Case management overview Case types: Postmaster, abuse, LE reports Queues and the case lifecycle | D22: Understand how cases arrive in Sonar and how they are organised, worked and closed | E22: SPL | F22: 60 | G22: The time includes 45 mins course and 15 mins trainer facilitation where he/she clarifies the doubts and concerns. | H22: §10 Tools by stage, §14 Ops terms | I22: Partly ready – SME to add
B23: Hands on: Sonar | C23: Navigate a sample queue Open, read and update a sample case Record root cause and sub root cause | D23: Find, read and update a case in Sonar and record its classification correctly | E23: Activity | F23: 60 | H23: §14 Ops terms | I23: Ops to arrange
B24: Tools overview - part 2 (Proofpoint, Bazooka, Gattler) - Mitigate | C24: Proofpoint PPS/TAP: phishing, malware, URL defense, rules Bazooka Gattler | D24: Understand which mitigation tools the team uses and what each one blocks or actions | E24: Blended | F24: 90 | G24: The blended module - Trainees go through the self-paced module (60 mins), after which the trainer reinforces each workflow with the trainees (30 mins). | H24: §6 stage 7, §10 | I24: Partly ready – SME to add
B25: Quick Wrap-Up | C25: Key takeaways Open questions Exit ticket | D25: Consolidate the day's learning and note open questions for the next day's recap | E25: Activity | F25: 45 | I25: Trainer to build
A26: 4 | B26: Day 3 Recap | C26: Round-robin questions on Day 3 topics Open questions from the wrap-up | D26: Check what trainees retained from Day 3 and close gaps before new content | E26: Activity | F26: 45 | I26: Trainer to build
B27: Tools overview - part 3 (Radar, Slack, Quip) - Engineer | C27: Radar: engineering escalation and feature requests Slack: coordination Quip: SOPs and reports | D27: Know how ops findings are escalated to Engineering and where SOPs and reports live | E27: SPL | F27: 45 | G27: The time includes 30 mins course and 15 mins trainer facilitation where he/she clarifies the doubts and concerns. | H27: §10 Tools by stage | I27: Partly ready – SME to add
B28: Tools overview - part 4 (Khiron, iHawk) - Other tools | C28: Khiron iHawk | D28: Know what Khiron and iHawk are used for and when an analyst needs them | E28: SPL | F28: 45 | G28: The time includes 30 mins course and 15 mins trainer facilitation where he/she clarifies the doubts and concerns. Slack and Quip are covered in part 3, so they are dropped here to avoid repetition. | I28: SME to provide
B29: Hands on: Tools by stage | C29: Match the tool to the task: Identify, Mitigate, Engineer, Collaborate | D29: Pick the right tool for a given task and say where it sits in the operating model | E29: Activity | F29: 60 | H29: §10 Tools by stage | I29: Trainer to build
B30: The 14-stage milter chain | C30: Authentication, stages 1-6: Heimdall Connect, SPF, DKIM, DMARC, ARC, BIMI Enterprise, stage 7: Proofpoint Intelligence, stages 8-14: Heimdall ML, ETL, Final Milter, HME, ARA, Categorization, Mantis Processing paths and fail-open behaviour | D30: Name each milter stage, what it checks and the analyst takeaway, and explain why a spike in spam reports can mean an outage rather than a campaign | E30: Blended | F30: 90 | G30: The blended module - Trainees go through the self-paced module (60 mins), after which the trainer reinforces each workflow with the trainees (30 mins). | H30: §6 | I30: Ready – Module 1 guide
B31: Hands on: Header analysis with samples | C31: Read Authentication-Results headers Map header evidence to milter stages Spot spoofing, forwarding (ARC) and Hide My Email relay headers | D31: Analyse sample headers and explain which stages each message passed or failed, and why | E31: Activity | F31: 90 | G31: Covers the SME's 'Header analysis with samples' item | H31: §6, §14 Email fundamentals | I31: SME to provide
B32: Quick Wrap-Up | C32: Key takeaways Open questions Exit ticket | D32: Consolidate the day's learning and note open questions for the next day's recap | E32: Activity | F32: 45 | I32: Trainer to build
A33: 5 | B33: Day 4 Recap | C33: Round-robin questions on Day 4 topics Open questions from the wrap-up | D33: Check what trainees retained from Day 4 and close gaps before new content | E33: Activity | F33: 45 | I33: Trainer to build
B34: Inbound Mail Flow: Deep Dive | C34: Front door: Heimdall Connect, Spamhaus, NFTrack ID check: SPF, DKIM, DMARC, ARC Security scan: Proofpoint, Heimdall ML, Mantis Final decision and sorting: Final Milter, ARA, Categorization | D34: Trace an inbound message checkpoint by checkpoint and explain what a block at each one usually means | E34: Blended | F34: 90 | G34: The blended module - Trainees go through the self-paced module (60 mins), after which the trainer reinforces each workflow with the trainees (30 mins). | H34: §5, §6 | I34: Ready – Module 1 guide
B35: Hands on: Inbound mail tracing | C35: Trace sample inbound messages Explain where and why each one was stopped or delivered | D35: Follow real examples through the inbound flow and justify each verdict | E35: Activity | F35: 75 | H35: Guide: Weeks 2-3 tasks | I35: SME to provide
B36: Outbound Mail Flow: Deep Dive | C36: Sending: Iscream (apps), MccGateway/MailWS2 (web) Quick check: Dragon Sending limits: NFTrack Outbound milters and DKIM signing (ASMTP) Retries, bounces and outbound abuse signals | D36: Trace an outbound message end to end and recognise the signals of outbound abuse | E36: Blended | F36: 90 | G36: The blended module - Trainees go through the self-paced module (60 mins), after which the trainer reinforces each workflow with the trainees (30 mins). | H36: §7 | I36: Ready – Module 1 guide
B37: Hands on: Outbound mail tracing | C37: Trace sample outbound messages Read bounces: 4xx vs 5xx Spot quota hits and harvested-list bounce patterns | D37: Follow examples through the outbound flow and spot early signs of abuse | E37: Activity | F37: 75 | H37: §7, §14 | I37: SME to provide
B38: Quick Wrap-Up | C38: Key takeaways Open questions Exit ticket | D38: Consolidate the day's learning and note open questions for the next day's recap | E38: Activity | F38: 45 | I38: Trainer to build
A39: WEEK 2 · Abuse, account actions, Postmaster and triage (Days 6–10)
A40: 6 | B40: Week 1 Knowledge Check | C40: Days 1-5: product, privacy, architecture, tools, milter chain, mail flows | D40: Confirm the foundations are in place before abuse and casework begin | E40: Assessment | F40: 60 | G40: Uses the Module 1 self-check quiz (§16) plus trainer-built questions. Pass mark to be agreed with Ops | H40: §16 | I40: Trainer to build
B41: Knowledge Check Review | C41: Walk through the answers Revisit weak areas | D41: Close the gaps the knowledge check found | E41: Activity | F41: 45 | I41: Trainer to build
...

Sheet Summary
A1: Summary – 15-Day Mail OPS Curriculum
A2: Minutes and hours are formulas over the 15-Day Curriculum sheet, so they update when session times change.
A4: Day by day
A5: Day | B5: Week | C5: Theme | D5: Mins | E5: Hours | F5: Checkpoint | G5: Maps to SME 10-day plan
A6: 1 | B6: 1 | C6: Team, privacy and the iCloud Mail product | D6: =SUM('15-Day Curriculum'!F6:F11) -> 420 | E6: =D6/60 -> 7 | G6: SME Day 1
A7: 2 | B7: 1 | C7: Mail flow architecture, Heimdall and URL/SUPs | D7: =SUM('15-Day Curriculum'!F12:F18) -> 420 | E7: =D7/60 -> 7 | G7: SME Day 2 (architecture, headers, Heimdall) + SME Day 3 (URL/SUP)
A8: 3 | B8: 1 | C8: Investigate and mitigate tools | D8: =SUM('15-Day Curriculum'!F19:F25) -> 420 | E8: =D8/60 -> 7 | G8: SME Day 3 (Splunk, Tools, Hands-on)
A9: 4 | B9: 1 | C9: Engineer and other tools, the 14-stage milter chain, header analysis | D9: =SUM('15-Day Curriculum'!F26:F32) -> 420 | E9: =D9/60 -> 7 | G9: SME Day 3 (Tools) + SME Day 2 (milter chain, header samples)
A10: 5 | B10: 1 | C10: Inbound and outbound mail flow deep dives | D10: =SUM('15-Day Curriculum'!F33:F38) -> 420 | E10: =D10/60 -> 7 | G10: SME Day 2 (inbound and outbound architecture), extended
A11: 6 | B11: 2 | C11: Knowledge check, operating model and abuse landscape | D11: =SUM('15-Day Curriculum'!F40:F45) -> 420 | E11: =D11/60 -> 7 | F11: Week 1 knowledge check | G11: SME Day 4 (abuse landscape in iCloud Outbound)
A12: 7 | B12: 2 | C12: Account actions and actioning a case | D12: =SUM('15-Day Curriculum'!F46:F50) -> 420 | E12: =D12/60 -> 7 | G12: SME Day 4 (types/actions on accounts) + SME Day 5 (hands-on)
A13: 8 | B13: 2 | C13: Hands-on with sample accounts | D13: =SUM('15-Day Curriculum'!F51:F54) -> 420 | E13: =D13/60 -> 7 | G13: SME Day 6
A14: 9 | B14: 2 | C14: Postmaster and triage playbooks | D14: =SUM('15-Day Curriculum'!F55:F60) -> 420 | E14: =D14/60 -> 7 | G14: New – not in SME plan
A15: 10 | B15: 2 | C15: Scenario practice and Week 2 assessment | D15: =SUM('15-Day Curriculum'!F61:F65) -> 420 | E15: =D15/60 -> 7 | F15: Week 2 practical assessment | G15: New – not in SME plan
A16: 11 | B16: 3 | C16: Campaigns and engineering hand-offs | D16: =SUM('15-Day Curriculum'!F67:F71) -> 420 | E16: =D16/60 -> 7 | G16: SME Day 7
A17: 12 | B17: 3 | C17: Outbound hands-on | D17: =SUM('15-Day Curriculum'!F72:F75) -> 420 | E17: =D17/60 -> 7 | G17: SME Day 8
A18: 13 | B18: 3 | C18: Outbound hands-on and working with senior analysts | D18: =SUM('15-Day Curriculum'!F76:F80) -> 420 | E18: =D18/60 -> 7 | G18: SME Day 9 + guide Weeks 2-3 tasks
A19: 14 | B19: 3 | C19: Nesting: supervised mixed queue | D19: =SUM('15-Day Curriculum'!F81:F85) -> 420 | E19: =D19/60 -> 7 | G19: SME Day 10 (outbound hands-on) + nesting
A20: 15 | B20: 3 | C20: Final certification and transition to process | D20: =SUM('15-Day Curriculum'!F86:F91) -> 420 | E20: =D20/60 -> 7 | F20: Final certification | G20: New – not in SME plan
A21: Total | D21: =SUM(D6:D20) -> 6300 | E21: =SUM(E6:E20) -> 105
A23: Time by modality
A24: Modality | C24: Sessions | D24: Mins | E24: Hours | F24: Share of time | G24: What it means
A25: SPL | C25: =COUNTIF('15-Day Curriculum'!$E$5:$E$91,A25) -> 11 | D25: =SUMIF('15-Day Curriculum'!$E$5:$E$91,A25,'15-Day Curriculum'!$F$5:$F$91) -> 600 | E25: =D25/60 -> 10 | F25: =IF($D$21=0,0,D25/$D$21) -> 0.095238095 | G25: Self-paced learning module, followed by trainer facilitation for doubts (split shown in Remarks)
A26: Blended | C26: =COUNTIF('15-Day Curriculum'!$E$5:$E$91,A26) -> 11 | D26: =SUMIF('15-Day Curriculum'!$E$5:$E$91,A26,'15-Day Curriculum'!$F$5:$F$91) -> 960 | E26: =D26/60 -> 16 | F26: =IF($D$21=0,0,D26/$D$21) -> 0.15238095 | G26: Self-paced module first, then the trainer reinforces each workflow (split shown in Remarks)
A27: ILT | C27: =COUNTIF('15-Day Curriculum'!$E$5:$E$91,A27) -> 12 | D27: =SUMIF('15-Day Curriculum'!$E$5:$E$91,A27,'15-Day Curriculum'!$F$5:$F$91) -> 900 | E27: =D27/60 -> 15 | F27: =IF($D$21=0,0,D27/$D$21) -> 0.14285714 | G27: Instructor-led session or live demo
A28: Activity | C28: =COUNTIF('15-Day Curriculum'!$E$5:$E$91,A28) -> 46 | D28: =SUMIF('15-Day Curriculum'!$E$5:$E$91,A28,'15-Day Curriculum'!$F$5:$F$91) -> 3450 | E28: =D28/60 -> 57.5 | F28: =IF($D$21=0,0,D28/$D$21) -> 0.54761905 | G28: Hands-on practice, recaps and wrap-ups
A29: Assessment | C29: =COUNTIF('15-Day Curriculum'!$E$5:$E$91,A29) -> 4 | D29: =SUMIF('15-Day Curriculum'!$E$5:$E$91,A29,'15-Day Curriculum'!$F$5:$F$91) -> 390 | E29: =D29/60 -> 6.5 | F29: =IF($D$21=0,0,D29/$D$21) -> 0.061904762 | G29: Scored knowledge check, practical assessment or certification
A30: Total | C30: =SUM(C25:C29) -> 84 | D30: =SUM(D25:D29) -> 6300 | E30: =SUM(E25:E29) -> 105 | F30: =SUM(F25:F29) -> 1
A32: Content readiness
A33: Content status | C33: Sessions | D33: Mins | E33: Hours | F33: Share of time | G33: What it means
A34: Ready – Module 1 guide | C34: =COUNTIF('15-Day Curriculum'!$I$5:$I$91,A34) -> 12 | D34: =SUMIF('15-Day Curriculum'!$I$5:$I$91,A34,'15-Day Curriculum'!$F$5:$F$91) -> 870 | E34: =D34/60 -> 14.5 | F34: =IF($D$21=0,0,D34/$D$21) -> 0.13809524 | G34: Content exists in the Module 1 learning guide (section shown in the Guide ref column)
A35: Partly ready – SME to add | C35: =COUNTIF('15-Day Curriculum'!$I$5:$I$91,A35) -> 8 | D35: =SUMIF('15-Day Curriculum'!$I$5:$I$91,A35,'15-Day Curriculum'!$F$5:$F$91) -> 555 | E35: =D35/60 -> 9.25 | F35: =IF($D$21=0,0,D35/$D$21) -> 0.088095238 | G35: Module 1 covers the basics; the SME needs to add tool, SOP or policy detail
A36: SME to provide | C36: =COUNTIF('15-Day Curriculum'!$I$5:$I$91,A36) -> 18 | D36: =SUMIF('15-Day Curriculum'!$I$5:$I$91,A36,'15-Day Curriculum'!$F$5:$F$91) -> 2040 | E36: =D36/60 -> 34 | F36: =IF($D$21=0,0,D36/$D$21) -> 0.32380952 | G36: Content, samples or data must come from the SME (see the SME inputs sheet)
A37: Trainer to build | C37: =COUNTIF('15-Day Curriculum'!$I$5:$I$91,A37) -> 39 | D37: =SUMIF('15-Day Curriculum'!$I$5:$I$91,A37,'15-Day Curriculum'!$F$5:$F$91) -> 2145 | E37: =D37/60 -> 35.75 | F37: =IF($D$21=0,0,D37/$D$21) -> 0.34047619 | G37: Trainer builds the activity, quiz or rubric from existing content
A38: Ops to arrange | C38: =COUNTIF('15-Day Curriculum'!$I$5:$I$91,A38) -> 7 | D38: =SUMIF('15-Day Curriculum'!$I$5:$I$91,A38,'15-Day Curriculum'!$F$5:$F$91) -> 690 | E38: =D38/60 -> 11.5 | F38: =IF($D$21=0,0,D38/$D$21) -> 0.10952381 | G38: Needs access, accounts, people or a queue arranged by Ops
A39: Total | C39: =SUM(C34:C38) -> 84 | D39: =SUM(D34:D38) -> 6300 | E39: =SUM(E34:E38) -> 105 | F39: =SUM(F34:F38) -> 1
A41: How this plan differs from the SME's 10-day plan
A42: • Topic order follows the Mail OPS draft: URL/SUPs on Day 2, the 14-stage milter chain on Day 4. The SME's 'Header analysis with samples' is kept as a Day 4 hands-on right after the chain.
A43: • Scope covers inbound, outbound and Postmaster, so Postmaster, the inbound deep dive, the triage playbooks and the operating model are added (not in the SME's 10-day plan).
A44: • Sample-account practice is about one day (Days 7-8) against two days in the SME plan, to make room for Postmaster and inbound work.
...

Sheet SME inputs
A1: Inputs needed before delivery
A2: Update the Status column (dropdown: Open, Requested, Received) as items come in.
A4: # | B4: Item | C4: Needed for | D4: What's needed | E4: Owner | F4: Status
A5: 1 | B5: Trainee tool access | C5: Before Day 3 | D5: Sonar, Splunk, Proofpoint, Heimdall, Radar, Slack and YubiKey/MFA access in place for the hands-on sessions | E5: Ops | F5: Open
A6: 2 | B6: Test iCloud accounts | C6: Day 1 | D6: iCloud accounts (with iCloud+) and device or webmail access for the Day 1 hands-on | E6: Ops | F6: Open
A7: 3 | B7: Apple ecosystem, T&S intro, GDPR and privacy incidents | C7: Day 1 | D7: Content for the parts of the mission and privacy modules that the Module 1 guide doesn't cover | E7: SME | F7: Open
A8: 4 | B8: URL/SUP | C8: Day 2 | D8: What URL/SUP is, its sub-topics, modality, duration and sample requests | E8: SME | F8: Open
A9: 5 | B9: Heimdall UI, naming convention and rule writing | C9: Day 2 | D9: Content and a demo login for the Heimdall overview and walkthrough | E9: SME | F9: Open
A10: 6 | B10: Sanitised email header samples | C10: Days 2, 4, 10 | D10: Privacy-safe real headers covering passes, fails, spoofing, forwarding (ARC) and HME relay | E10: SME | F10: Open
A11: 7 | B11: Splunk indexes and starter queries | C11: Day 3 | D11: Index list and a query library for the Splunk module and hands-on | E11: SME | F11: Open
A12: 8 | B12: Sonar walkthrough and sample cases | C12: Day 3 | D12: UI walkthrough and a sandbox or sample cases | E12: SME | F12: Open
A13: 9 | B13: Bazooka and Gattler | C13: Day 3 | D13: What each tool does, plus a demo | E13: SME | F13: Open
A14: 10 | B14: Khiron and iHawk | C14: Day 4 | D14: What each tool does and when analysts use it | E14: SME | F14: Open
A15: 11 | B15: Inbound and outbound tracing samples | C15: Day 5 | D15: Sample messages with known verdicts for the tracing exercises | E15: SME | F15: Open
A16: 12 | B16: Bad forward, HME + bad forward, login alias, Apple ID abuse | C16: Day 6 | D16: Definitions, signals and examples (bad forward is not in the Module 1 guide) | E16: SME | F16: Open
... A25: 21 | B25: Module 2: Spam and phishing deep dive | C25: Days 6, 9 | D25: The guide's course map lists Module 2 as available; only Module 1 has been shared | E25: SME | F25: Open
